Workbook

Sheet Matriz Criterios
A1: MATRIZ DE SELECCIÓN DE CRITERIOS DE EVALUACIÓN POR TAREA — DESARROLLO DE INTERFACES (2º DAM)
A2: Marca con una 'X' en la casilla correspondiente para activar los criterios evaluados en cada tarea. Los porcentajes y notas se recalcularán automáticamente.
A4: CRITERIOS OFICIALES DE EVALUACIÓN (DECRETO 104/2024 & RD 405/2023) | H4: 1er TRIMESTRE (T1) — TAREAS Y PRUEBAS | O4: 2º TRIMESTRE (T2) — TAREAS, PRUEBAS Y PROYECTO | W4: Pond. CE Global
A5: RA | B5: Peso RA | C5: Código CE | D5: Descripción Oficial del Criterio de Evaluación | E5: UDs | F5: Total Tareas | G5: Estado Cobertura | H5: T01 Figma & UX | I5: T02 NUI & Voz | J5: T03 Tailwind & Grid | K5: T04 Accesibilidad | L5: T05 Angular Signals | M5: T06 Examen Práctico T1 | N5: T07 Git & Actitud T1 | O5: T08 Formularios & A11y | P5: T09 Storybook & Design | Q5: T10 Informes & Dashboards | R5: T11 Pruebas Vitest | S5: T12 Electron Desktop | T5: T13 Proyecto GesFlow | U5: T14 Examen Práctico T2 | V5: T15 Git & Despliegue T2
A6: RA1 | B6: 0.22 | C6: CE1.a | D6: Se han identificado los elementos que componen la interfaz gráfica. | E6: UD00, UD01 | F6: =COUNTIF(H6:V6, "X") | G6: =IF(F6>0, "EVALUADO", "SIN EVALUAR") | H6: X | M6: X | T6: X | W6: =B6 / COUNTIF(A$6:A$45, A6)
A7: RA1 | B7: 0.22 | C7: CE1.b | D7: Se han analizado los principios de usabilidad y diseño centrado en el usuario (UX). | E7: UD01 | F7: =COUNTIF(H7:V7, "X") | G7: =IF(F7>0, "EVALUADO", "SIN EVALUAR") | H7: X | M7: X | W7: =B7 / COUNTIF(A$6:A$45, A7)
A8: RA1 | B8: 0.22 | C8: CE1.c | D8: Se han elaborado bocetos, wireframes y prototipos interactivos en alta fidelidad (Figma). | E8: UD04 | F8: =COUNTIF(H8:V8, "X") | G8: =IF(F8>0, "EVALUADO", "SIN EVALUAR") | H8: X | M8: X | P8: X | T8: X | W8: =B8 / COUNTIF(A$6:A$45, A8)
A9: RA1 | B9: 0.22 | C9: CE1.d | D9: Se han aplicado guías de estilo, tipografías, colores, espaciados y sistemas de diseño. | E9: UD07, UD13 | F9: =COUNTIF(H9:V9, "X") | G9: =IF(F9>0, "EVALUADO", "SIN EVALUAR") | H9: X | J9: X | P9: X | T9: X | W9: =B9 / COUNTIF(A$6:A$45, A9)
A10: RA1 | B10: 0.22 | C10: CE1.e | D10: Se han diseñado layouts modernos y adaptables (CSS Grid, Flexbox, Tailwind CSS v4). | E10: UD05, UD06, UD08 | F10: =COUNTIF(H10:V10, "X") | G10: =IF(F10>0, "EVALUADO", "SIN EVALUAR") | J10: X | M10: X | T10: X | W10: =B10 / COUNTIF(A$6:A$45, A10)
A11: RA1 | B11: 0.22 | C11: CE1.f | D11: Se ha verificado la correcta interacción y flujo de navegación entre pantallas. | E11: UD04, UD15 | F11: =COUNTIF(H11:V11, "X") | G11: =IF(F11>0, "EVALUADO", "SIN EVALUAR") | H11: X | M11: X | P11: X | T11: X | W11: =B11 / COUNTIF(A$6:A$45, A11)
A12: RA2 | B12: 0.16 | C12: CE2.a | D12: Se han identificado conceptos, arquitecturas y hardware de interfaces naturales (NUI). | E12: UD03 | F12: =COUNTIF(H12:V12, "X") | G12: =IF(F12>0, "EVALUADO", "SIN EVALUAR") | I12: X | M12: X | W12: =B12 / COUNTIF(A$6:A$45, A12)
A13: RA2 | B13: 0.16 | C13: CE2.b | D13: Se han integrado librerías y APIs de reconocimiento y síntesis de voz (Web Speech API). | E13: UD03 | F13: =COUNTIF(H13:V13, "X") | G13: =IF(F13>0, "EVALUADO", "SIN EVALUAR") | I13: X | M13: X | T13: X | W13: =B13 / COUNTIF(A$6:A$45, A13)
A14: RA2 | B14: 0.16 | C14: CE2.c | D14: Se han implementado controles basados en visión artificial y tracking de gestos/manos. | E14: UD03 | F14: =COUNTIF(H14:V14, "X") | G14: =IF(F14>0, "EVALUADO", "SIN EVALUAR") | I14: X | W14: =B14 / COUNTIF(A$6:A$45, A14)
A15: RA2 | B15: 0.16 | C15: CE2.d | D15: Se han explorado patrones de realidad aumentada y experiencias inmersivas (WebXR/Three.js). | E15: UD03 | F15: =COUNTIF(H15:V15, "X") | G15: =IF(F15>0, "EVALUADO", "SIN EVALUAR") | I15: X | W15: =B15 / COUNTIF(A$6:A$45, A15)
A16: RA2 | B16: 0.16 | C16: CE2.e | D16: Se han evaluado ventajas y barreras de accesibilidad de interfaces conversacionales y gestuales. | E16: UD03 | F16: =COUNTIF(H16:V16, "X") | G16: =IF(F16>0, "EVALUADO", "SIN EVALUAR") | I16: X | M16: X | W16: =B16 / COUNTIF(A$6:A$45, A16)
A17: RA3 | B17: 0.2 | C17: CE3.a | D17: Se ha seleccionado el framework y entorno de desarrollo (Angular 19+ Standalone). | E17: UD09, UD10 | F17: =COUNTIF(H17:V17, "X") | G17: =IF(F17>0, "EVALUADO", "SIN EVALUAR") | L17: X | M17: X | T17: X | W17: =B17 / COUNTIF(A$6:A$45, A17)
A18: RA3 | B18: 0.2 | C18: CE3.b | D18: Se han diseñado componentes reutilizables aplicando atomic design. | E18: UD11, UD13 | F18: =COUNTIF(H18:V18, "X") | G18: =IF(F18>0, "EVALUADO", "SIN EVALUAR") | L18: X | M18: X | P18: X | T18: X | W18: =B18 / COUNTIF(A$6:A$45, A18)
A19: RA3 | B19: 0.2 | C19: CE3.c | D19: Se ha gestionado el estado reactivo y comunicación de componentes (Signals, RxJS). | E19: UD10, UD11 | F19: =COUNTIF(H19:V19, "X") | G19: =IF(F19>0, "EVALUADO", "SIN EVALUAR") | L19: X | M19: X | O19: X | T19: X | U19: X | W19: =B19 / COUNTIF(A$6:A$45, A19)
A20: RA3 | B20: 0.2 | C20: CE3.d | D20: Se han integrado directivas, pipes personalizados e inyección de dependencias. | E20: UD10, UD11 | F20: =COUNTIF(H20:V20, "X") | G20: =IF(F20>0, "EVALUADO", "SIN EVALUAR") | L20: X | O20: X | T20: X | W20: =B20 / COUNTIF(A$6:A$45, A20)
A21: RA3 | B21: 0.2 | C21: CE3.e | D21: Se ha documentado e interactuado con la librería de componentes mediante Storybook. | E21: UD14 | F21: =COUNTIF(H21:V21, "X") | G21: =IF(F21>0, "EVALUADO", "SIN EVALUAR") | P21: X | T21: X | W21: =B21 / COUNTIF(A$6:A$45, A21)
A22: RA3 | B22: 0.2 | C22: CE3.f | D22: Se han creado formularios reactivos con validaciones asíncronas y accesibles. | E22: UD12 | F22: =COUNTIF(H22:V22, "X") | G22: =IF(F22>0, "EVALUADO", "SIN EVALUAR") | O22: X | T22: X | U22: X | W22: =B22 / COUNTIF(A$6:A$45, A22)
A23: RA4 | B23: 0.11 | C23: CE4.a | D23: Se han analizado las pautas WCAG 2.2 en niveles A, AA y AAA. | E23: UD02 | F23: =COUNTIF(H23:V23, "X") | G23: =IF(F23>0, "EVALUADO", "SIN EVALUAR") | K23: X | M23: X | W23: =B23 / COUNTIF(A$6:A$45, A23)
A24: RA4 | B24: 0.11 | C24: CE4.b | D24: Se han verificado atributos semánticos WAI-ARIA (roles, states, live regions). | E24: UD02, UD12 | F24: =COUNTIF(H24:V24, "X") | G24: =IF(F24>0, "EVALUADO", "SIN EVALUAR") | K24: X | O24: X | T24: X | W24: =B24 / COUNTIF(A$6:A$45, A24)
A25: RA4 | B25: 0.11 | C25: CE4.c | D25: Se ha asegurado navegación por teclado, focos visibles y ratios de contraste. | E25: UD02, UD08 | F25: =COUNTIF(H25:V25, "X") | G25: =IF(F25>0, "EVALUADO", "SIN EVALUAR") | K25: X | M25: X | O25: X | T25: X | W25: =B25 / COUNTIF(A$6:A$45, A25)
A26: RA4 | B26: 0.11 | C26: CE4.d | D26: Se han ejecutado auditorías automáticas de accesibilidad (Axe Core, Lighthouse). | E26: UD02 | F26: =COUNTIF(H26:V26, "X") | G26: =IF(F26>0, "EVALUADO", "SIN EVALUAR") | K26: X | T26: X | W26: =B26 / COUNTIF(A$6:A$45, A26)
A27: RA4 | B27: 0.11 | C27: CE4.e | D27: Se han realizado pruebas de compatibilidad con lectores de pantalla (NVDA, VoiceOver). | E27: UD02, UD12 | F27: =COUNTIF(H27:V27, "X") | G27: =IF(F27>0, "EVALUADO", "SIN EVALUAR") | K27: X | O27: X | W27: =B27 / COUNTIF(A$6:A$45, A27)
A28: RA5 | B28: 0.04 | C28: CE5.a | D28: Se han seleccionado herramientas y librerías de generación de documentos (jsPDF, SheetJS). | E28: UD16 | F28: =COUNTIF(H28:V28, "X") | G28: =IF(F28>0, "EVALUADO", "SIN EVALUAR") | Q28: X | T28: X | U28: X | W28: =B28 / COUNTIF(A$6:A$45, A28)
A29: RA5 | B29: 0.04 | C29: CE5.b | D29: Se han diseñado plantillas de informes estructurados con tablas y paginación. | E29: UD16 | F29: =COUNTIF(H29:V29, "X") | G29: =IF(F29>0, "EVALUADO", "SIN EVALUAR") | Q29: X | T29: X | W29: =B29 / COUNTIF(A$6:A$45, A29)
A30: RA5 | B30: 0.04 | C30: CE5.c | D30: Se han creado cuadros de mando interactivos con visualización de datos (Chart.js). | E30: UD17 | F30: =COUNTIF(H30:V30, "X") | G30: =IF(F30>0, "EVALUADO", "SIN EVALUAR") | Q30: X | T30: X | W30: =B30 / COUNTIF(A$6:A$45, A30)
A31: RA5 | B31: 0.04 | C31: CE5.d | D31: Se han implementado filtros dinámicos y exportación en formatos estándar (PDF, Excel, CSV). | E31: UD17 | F31: =COUNTIF(H31:V31, "X") | G31: =IF(F31>0, "EVALUADO", "SIN EVALUAR") | Q31: X | T31: X | W31: =B31 / COUNTIF(A$6:A$45, A31)
A32: RA6 | B32: 0.07 | C32: CE6.a | D32: Se han identificado destinatarios y requisitos de la documentación técnica y de usuario. | E32: UD18 | F32: =COUNTIF(H32:V32, "X") | G32: =IF(F32>0, "EVALUADO", "SIN EVALUAR") | P32: X | T32: X | W32: =B32 / COUNTIF(A$6:A$45, A32)
A33: RA6 | B33: 0.07 | C33: CE6.b | D33: Se han generado esquemas, diagramas de flujo y arquitectura de la interfaz. | E33: UD18 | F33: =COUNTIF(H33:V33, "X") | G33: =IF(F33>0, "EVALUADO", "SIN EVALUAR") | P33: X | T33: X | W33: =B33 / COUNTIF(A$6:A$45, A33)
A34: RA6 | B34: 0.07 | C34: CE6.c | D34: Se ha automatizado la generación de documentación de componentes (Compodoc, Storybook). | E34: UD14, UD18 | F34: =COUNTIF(H34:V34, "X") | G34: =IF(F34>0, "EVALUADO", "SIN EVALUAR") | P34: X | T34: X | W34: =B34 / COUNTIF(A$6:A$45, A34)
A35: RA6 | B35: 0.07 | C35: CE6.d | D35: Se han redactado guías de estilo, manuales interactivos y ayuda en línea (Zensical/Markdown). | E35: UD18 | F35: =COUNTIF(H35:V35, "X") | G35: =IF(F35>0, "EVALUADO", "SIN EVALUAR") | P35: X | T35: X | W35: =B35 / COUNTIF(A$6:A$45, A35)
A36: RA7 | B36: 0.1 | C36: CE7.a | D36: Se han identificado entornos de ejecución y plataformas de destino (Windows, macOS, Linux). | E36: UD20 | F36: =COUNTIF(H36:V36, "X") | G36: =IF(F36>0, "EVALUADO", "SIN EVALUAR") | S36: X | T36: X | W36: =B36 / COUNTIF(A$6:A$45, A36)
A37: RA7 | B37: 0.1 | C37: CE7.b | D37: Se ha integrado la aplicación Angular en un contenedor de escritorio con Electron. | E37: UD20 | F37: =COUNTIF(H37:V37, "X") | G37: =IF(F37>0, "EVALUADO", "SIN EVALUAR") | S37: X | T37: X | U37: X | W37: =B37 / COUNTIF(A$6:A$45, A37)
A38: RA7 | B38: 0.1 | C38: CE7.c | D38: Se ha configurado la comunicación IPC segura (Preload Scripts, Context Isolation). | E38: UD20 | F38: =COUNTIF(H38:V38, "X") | G38: =IF(F38>0, "EVALUADO", "SIN EVALUAR") | S38: X | T38: X | U38: X | W38: =B38 / COUNTIF(A$6:A$45, A38)
A39: RA7 | B39: 0.1 | C39: CE7.d | D39: Se han generado paquetes e instaladores multiplataforma (Forge, Builder, MSIX, AppImage). | E39: UD21 | F39: =COUNTIF(H39:V39, "X") | G39: =IF(F39>0, "EVALUADO", "SIN EVALUAR") | S39: X | T39: X | W39: =B39 / COUNTIF(A$6:A$45, A39)
A40: RA7 | B40: 0.1 | C40: CE7.e | D40: Se han configurado actualizaciones automáticas y firmas de ejecutables. | E40: UD21 | F40: =COUNTIF(H40:V40, "X") | G40: =IF(F40>0, "EVALUADO", "SIN EVALUAR") | S40: X | W40: =B40 / COUNTIF(A$6:A$45, A40)
A41: RA8 | B41: 0.1 | C41: CE8.a | D41: Se ha planificado la estrategia de pruebas de la interfaz de usuario. | E41: UD19 | F41: =COUNTIF(H41:V41, "X") | G41: =IF(F41>0, "EVALUADO", "SIN EVALUAR") | R41: X | T41: X | W41: =B41 / COUNTIF(A$6:A$45, A41)
...

Sheet Registro Notas
A1: REGISTRO DE CALIFICACIONES POR TAREA — DESARROLLO DE INTERFACES (2º DAM)
A2: Introduce las calificaciones obtenidas por cada alumno/a (0 a 10). Las notas trimestrales y el progreso por criterios se calculan en tiempo real.
A4: DATOS DEL ALUMNADO | D4: TAREAS 1er TRIMESTRE (T1) | K4: TAREAS 2º TRIMESTRE (T2) | S4: CALIFICACIONES TRIMESTRALES
A5: Nº | B5: Apellidos, Nombre | C5: Grupo | D5: T01 (15%) Figma UX | E5: T02 (15%) NUI Voz | F5: T03 (15%) Tailwind | G5: T04 (15%) Accesib. | H5: T05 (15%) Angular | I5: T06 (20%) Examen T1 | J5: T07 (5%) Git T1 | K5: T08 (10%) Forms A11y | L5: T09 (10%) Storybook | M5: T10 (10%) Informes | N5: T11 (10%) Vitest/E2E | O5: T12 (10%) Electron | P5: T13 (25%) GesFlow | Q5: T14 (20%) Examen T2 | R5: T15 (5%) Git T2 | S5: 1º TRIMESTRE (Ponderado T1) | T5: 2º TRIMESTRE (Ponderado T2)
A6: 1 | B6: Álvarez Gómez, Laura | C6: 2º DAM | D6: 8.5 | E6: 9 | F6: 8 | G6: 8.5 | H6: 9 | I6: 8.5 | J6: 9 | K6: 8.5 | L6: 9 | M6: 8.5 | N6: 9 | O6: 8.5 | P6: 9 | Q6: 8.5 | R6: 9.5 | S6: =D6*'Matriz Criterios'!H$47 + E6*'Matriz Criterios'!I$47 + F6*'Matriz Criterios'!J$47 + G6*'Matriz Criterios'!K$47 + H6*'Matriz Criterios'!L$47 + I6*'Matriz Criterios'!M$47 + J6*'Matriz Criterios'!N$47 | T6: =K6*'Matriz Criterios'!O$47 + L6*'Matriz Criterios'!P$47 + M6*'Matriz Criterios'!Q$47 + N6*'Matriz Criterios'!R$47 + O6*'Matriz Criterios'!S$47 + P6*'Matriz Criterios'!T$47 + Q6*'Matriz Criterios'!U$47 + R6*'Matriz Criterios'!V$47
A7: 2 | B7: Benítez Romero, Carlos | C7: 2º DAM | D7: 6 | E7: 5.5 | F7: 6.5 | G7: 7 | H7: 6 | I7: 6 | J7: 7 | K7: 6.5 | L7: 6 | M7: 7 | N7: 6.5 | O7: 6 | P7: 6.5 | Q7: 6 | R7: 7 | S7: =D7*'Matriz Criterios'!H$47 + E7*'Matriz Criterios'!I$47 + F7*'Matriz Criterios'!J$47 + G7*'Matriz Criterios'!K$47 + H7*'Matriz Criterios'!L$47 + I7*'Matriz Criterios'!M$47 + J7*'Matriz Criterios'!N$47 | T7: =K7*'Matriz Criterios'!O$47 + L7*'Matriz Criterios'!P$47 + M7*'Matriz Criterios'!Q$47 + N7*'Matriz Criterios'!R$47 + O7*'Matriz Criterios'!S$47 + P7*'Matriz Criterios'!T$47 + Q7*'Matriz Criterios'!U$47 + R7*'Matriz Criterios'!V$47
A8: 3 | B8: Castillo Morales, Elena | C8: 2º DAM | D8: 9.5 | E8: 9 | F8: 10 | G8: 9.5 | H8: 10 | I8: 9.5 | J8: 10 | K8: 10 | L8: 9.5 | M8: 9.5 | N8: 10 | O8: 9.5 | P8: 10 | Q8: 10 | R8: 10 | S8: =D8*'Matriz Criterios'!H$47 + E8*'Matriz Criterios'!I$47 + F8*'Matriz Criterios'!J$47 + G8*'Matriz Criterios'!K$47 + H8*'Matriz Criterios'!L$47 + I8*'Matriz Criterios'!M$47 + J8*'Matriz Criterios'!N$47 | T8: =K8*'Matriz Criterios'!O$47 + L8*'Matriz Criterios'!P$47 + M8*'Matriz Criterios'!Q$47 + N8*'Matriz Criterios'!R$47 + O8*'Matriz Criterios'!S$47 + P8*'Matriz Criterios'!T$47 + Q8*'Matriz Criterios'!U$47 + R8*'Matriz Criterios'!V$47
A9: 4 | B9: Delgado Santos, Alejandro | C9: 2º DAM | D9: 4 | E9: 5 | F9: 4.5 | G9: 5.5 | H9: 4 | I9: 4.5 | J9: 6 | K9: 5 | L9: 4.5 | M9: 5 | N9: 4.5 | O9: 5 | P9: 4.5 | Q9: 4 | R9: 5 | S9: =D9*'Matriz Criterios'!H$47 + E9*'Matriz Criterios'!I$47 + F9*'Matriz Criterios'!J$47 + G9*'Matriz Criterios'!K$47 + H9*'Matriz Criterios'!L$47 + I9*'Matriz Criterios'!M$47 + J9*'Matriz Criterios'!N$47 | T9: =K9*'Matriz Criterios'!O$47 + L9*'Matriz Criterios'!P$47 + M9*'Matriz Criterios'!Q$47 + N9*'Matriz Criterios'!R$47 + O9*'Matriz Criterios'!S$47 + P9*'Matriz Criterios'!T$47 + Q9*'Matriz Criterios'!U$47 + R9*'Matriz Criterios'!V$47
A10: 5 | B10: Fernández Navarro, Lucía | C10: 2º DAM | D10: 7.5 | E10: 8 | F10: 7 | G10: 7.5 | H10: 8 | I10: 7.5 | J10: 8.5 | K10: 7.5 | L10: 8 | M10: 8 | N10: 7.5 | O10: 8 | P10: 7.5 | Q10: 8 | R10: 8.5 | S10: =D10*'Matriz Criterios'!H$47 + E10*'Matriz Criterios'!I$47 + F10*'Matriz Criterios'!J$47 + G10*'Matriz Criterios'!K$47 + H10*'Matriz Criterios'!L$47 + I10*'Matriz Criterios'!M$47 + J10*'Matriz Criterios'!N$47 | T10: =K10*'Matriz Criterios'!O$47 + L10*'Matriz Criterios'!P$47 + M10*'Matriz Criterios'!Q$47 + N10*'Matriz Criterios'!R$47 + O10*'Matriz Criterios'!S$47 + P10*'Matriz Criterios'!T$47 + Q10*'Matriz Criterios'!U$47 + R10*'Matriz Criterios'!V$47
A11: 6 | B11: García Serrano, David | C11: 2º DAM | D11: 8 | E11: 7.5 | F11: 8.5 | G11: 8 | H11: 8.5 | I11: 8 | J11: 8.5 | K11: 8 | L11: 8.5 | M11: 8 | N11: 8.5 | O11: 8 | P11: 8.5 | Q11: 8 | R11: 8.5 | S11: =D11*'Matriz Criterios'!H$47 + E11*'Matriz Criterios'!I$47 + F11*'Matriz Criterios'!J$47 + G11*'Matriz Criterios'!K$47 + H11*'Matriz Criterios'!L$47 + I11*'Matriz Criterios'!M$47 + J11*'Matriz Criterios'!N$47 | T11: =K11*'Matriz Criterios'!O$47 + L11*'Matriz Criterios'!P$47 + M11*'Matriz Criterios'!Q$47 + N11*'Matriz Criterios'!R$47 + O11*'Matriz Criterios'!S$47 + P11*'Matriz Criterios'!T$47 + Q11*'Matriz Criterios'!U$47 + R11*'Matriz Criterios'!V$47
A12: 7 | B12: Herrera Cruz, Marta | C12: 2º DAM | D12: 9 | E12: 8.5 | F12: 9.5 | G12: 9 | H12: 9 | I12: 9 | J12: 9.5 | K12: 9 | L12: 9.5 | M12: 9 | N12: 9.5 | O12: 9 | P12: 9.5 | Q12: 9 | R12: 9.5 | S12: =D12*'Matriz Criterios'!H$47 + E12*'Matriz Criterios'!I$47 + F12*'Matriz Criterios'!J$47 + G12*'Matriz Criterios'!K$47 + H12*'Matriz Criterios'!L$47 + I12*'Matriz Criterios'!M$47 + J12*'Matriz Criterios'!N$47 | T12: =K12*'Matriz Criterios'!O$47 + L12*'Matriz Criterios'!P$47 + M12*'Matriz Criterios'!Q$47 + N12*'Matriz Criterios'!R$47 + O12*'Matriz Criterios'!S$47 + P12*'Matriz Criterios'!T$47 + Q12*'Matriz Criterios'!U$47 + R12*'Matriz Criterios'!V$47
A13: 8 | B13: Jiménez Ortiz, Pablo | C13: 2º DAM | D13: 5 | E13: 6 | F13: 5.5 | G13: 5 | H13: 6 | I13: 5.5 | J13: 6.5 | K13: 5.5 | L13: 6 | M13: 5.5 | N13: 6 | O13: 5.5 | P13: 6 | Q13: 5.5 | R13: 6.5 | S13: =D13*'Matriz Criterios'!H$47 + E13*'Matriz Criterios'!I$47 + F13*'Matriz Criterios'!J$47 + G13*'Matriz Criterios'!K$47 + H13*'Matriz Criterios'!L$47 + I13*'Matriz Criterios'!M$47 + J13*'Matriz Criterios'!N$47 | T13: =K13*'Matriz Criterios'!O$47 + L13*'Matriz Criterios'!P$47 + M13*'Matriz Criterios'!Q$47 + N13*'Matriz Criterios'!R$47 + O13*'Matriz Criterios'!S$47 + P13*'Matriz Criterios'!T$47 + Q13*'Matriz Criterios'!U$47 + R13*'Matriz Criterios'!V$47
A14: 9 | B14: López Molina, Sara | C14: 2º DAM | D14: 10 | E14: 9.5 | F14: 9.5 | G14: 10 | H14: 9.5 | I14: 10 | J14: 10 | K14: 10 | L14: 9.5 | M14: 10 | N14: 10 | O14: 9.5 | P14: 10 | Q14: 10 | R14: 10 | S14: =D14*'Matriz Criterios'!H$47 + E14*'Matriz Criterios'!I$47 + F14*'Matriz Criterios'!J$47 + G14*'Matriz Criterios'!K$47 + H14*'Matriz Criterios'!L$47 + I14*'Matriz Criterios'!M$47 + J14*'Matriz Criterios'!N$47 | T14: =K14*'Matriz Criterios'!O$47 + L14*'Matriz Criterios'!P$47 + M14*'Matriz Criterios'!Q$47 + N14*'Matriz Criterios'!R$47 + O14*'Matriz Criterios'!S$47 + P14*'Matriz Criterios'!T$47 + Q14*'Matriz Criterios'!U$47 + R14*'Matriz Criterios'!V$47
A15: 10 | B15: Martín Vega, Javier | C15: 2º DAM | D15: 3.5 | E15: 4 | F15: 4 | G15: 4.5 | H15: 4 | I15: 3.5 | J15: 5 | K15: 4 | L15: 4.5 | M15: 4 | N15: 4 | O15: 4.5 | P15: 4 | Q15: 4 | R15: 4.5 | S15: =D15*'Matriz Criterios'!H$47 + E15*'Matriz Criterios'!I$47 + F15*'Matriz Criterios'!J$47 + G15*'Matriz Criterios'!K$47 + H15*'Matriz Criterios'!L$47 + I15*'Matriz Criterios'!M$47 + J15*'Matriz Criterios'!N$47 | T15: =K15*'Matriz Criterios'!O$47 + L15*'Matriz Criterios'!P$47 + M15*'Matriz Criterios'!Q$47 + N15*'Matriz Criterios'!R$47 + O15*'Matriz Criterios'!S$47 + P15*'Matriz Criterios'!T$47 + Q15*'Matriz Criterios'!U$47 + R15*'Matriz Criterios'!V$47
A16: 11 | B16: Navarro Gil, Ana | C16: 2º DAM | D16: 8 | E16: 8.5 | F16: 8 | G16: 8.5 | H16: 8 | I16: 8.5 | J16: 9 | K16: 8.5 | L16: 8 | M16: 8.5 | N16: 8.5 | O16: 8 | P16: 8.5 | Q16: 8.5 | R16: 9 | S16: =D16*'Matriz Criterios'!H$47 + E16*'Matriz Criterios'!I$47 + F16*'Matriz Criterios'!J$47 + G16*'Matriz Criterios'!K$47 + H16*'Matriz Criterios'!L$47 + I16*'Matriz Criterios'!M$47 + J16*'Matriz Criterios'!N$47 | T16: =K16*'Matriz Criterios'!O$47 + L16*'Matriz Criterios'!P$47 + M16*'Matriz Criterios'!Q$47 + N16*'Matriz Criterios'!R$47 + O16*'Matriz Criterios'!S$47 + P16*'Matriz Criterios'!T$47 + Q16*'Matriz Criterios'!U$47 + R16*'Matriz Criterios'!V$47
A17: 12 | B17: Pérez Rubio, Álvaro | C17: 2º DAM | D17: 7 | E17: 6.5 | F17: 7.5 | G17: 7 | H17: 7 | I17: 7 | J17: 7.5 | K17: 7.5 | L17: 7 | M17: 7.5 | N17: 7 | O17: 7.5 | P17: 7 | Q17: 7.5 | R17: 7.5 | S17: =D17*'Matriz Criterios'!H$47 + E17*'Matriz Criterios'!I$47 + F17*'Matriz Criterios'!J$47 + G17*'Matriz Criterios'!K$47 + H17*'Matriz Criterios'!L$47 + I17*'Matriz Criterios'!M$47 + J17*'Matriz Criterios'!N$47 | T17: =K17*'Matriz Criterios'!O$47 + L17*'Matriz Criterios'!P$47 + M17*'Matriz Criterios'!Q$47 + N17*'Matriz Criterios'!R$47 + O17*'Matriz Criterios'!S$47 + P17*'Matriz Criterios'!T$47 + Q17*'Matriz Criterios'!U$47 + R17*'Matriz Criterios'!V$47
... A20: 15 | B20: Torres Lozano, Irene | C20: 2º DAM | D20: 9 | E20: 9.5 | F20: 9 | G20: 9.5 | H20: 9 | I20: 9.5 | J20: 9.5 | K20: 9.5 | L20: 9 | M20: 9.5 | N20: 10 | O20: 9.5 | P20: 9.5 | Q20: 9.5 | R20: 10 | S20: =D20*'Matriz Criterios'!H$47 + E20*'Matriz Criterios'!I$47 + F20*'Matriz Criterios'!J$47 + G20*'Matriz Criterios'!K$47 + H20*'Matriz Criterios'!L$47 + I20*'Matriz Criterios'!M$47 + J20*'Matriz Criterios'!N$47 | T20: =K20*'Matriz Criterios'!O$47 + L20*'Matriz Criterios'!P$47 + M20*'Matriz Criterios'!Q$47 + N20*'Matriz Criterios'!R$47 + O20*'Matriz Criterios'!S$47 + P20*'Matriz Criterios'!T$47 + Q20*'Matriz Criterios'!U$47 + R20*'Matriz Criterios'!V$47
A21: PROMEDIO DEL GRUPO | D21: =AVERAGE(D6:D20) | E21: =AVERAGE(E6:E20) | F21: =AVERAGE(F6:F20) | G21: =AVERAGE(G6:G20) | H21: =AVERAGE(H6:H20) | I21: =AVERAGE(I6:I20) | J21: =AVERAGE(J6:J20) | K21: =AVERAGE(K6:K20) | ... T21: =AVERAGE(T6:T20)

Sheet Calculo CEs
A1: CALIFICACIÓN DETALLADA POR CRITERIOS DE EVALUACIÓN (CE1.a a CE8.e) — DESARROLLO DE INTERFACES
A2: Cálculo matemático automático: cada criterio se calcula promediando exclusivamente las tareas donde tiene marcada una 'X' en la 'Matriz Criterios'.
A4: ALUMNADO | C4: RA1 (22%) — Interfaces Gráficas, UX, Figma y Layouts | I4: RA2 (16%) — Interfaces Naturales (NUI, Voz, Gestos) | N4: RA3 (20%) — Componentes Angular Standalone y Forms | T4: RA4 (11%) — Accesibilidad Universal y WCAG 2.2 | Y4: RA5 (4%) — Informes y Cuadros Mando | AC4: RA6 (7%) — Documentación Técnica y Storybook | AG4: RA7 (10%) — Escritorio Electron y Empaquetado | AL4: RA8 (10%) — Pruebas Vitest y Playwright E2E | AQ4: RESUMEN DE CRITERIOS
A5: Nº | B5: Apellidos, Nombre | C5: CE1.a | D5: CE1.b | E5: CE1.c | F5: CE1.d | G5: CE1.e | H5: CE1.f | I5: CE2.a | J5: CE2.b | K5: CE2.c | L5: CE2.d | M5: CE2.e | N5: CE3.a | O5: CE3.b | P5: CE3.c | Q5: CE3.d | R5: CE3.e | S5: CE3.f | T5: CE4.a | U5: CE4.b | V5: CE4.c | W5: CE4.d | X5: CE4.e | Y5: CE5.a | Z5: CE5.b | AA5: CE5.c | AB5: CE5.d | AC5: CE6.a | AD5: CE6.b | AE5: CE6.c | AF5: CE6.d | AG5: CE7.a | AH5: CE7.b | AI5: CE7.c | AJ5: CE7.d | AK5: CE7.e | AL5: CE8.a | AM5: CE8.b | AN5: CE8.c | AO5: CE8.d | AP5: CE8.e | AQ5: Media CEs Superados | AR5: Nº CEs >= 5 (de 40)
A6: 1 | B6: Álvarez Gómez, Laura | C6: =IF(SUMPRODUCT(('Matriz Criterios'!$H$6:$V$6="X")*ISNUMBER('Registro Notas'!$D6:$R6))=0, "-", SUMPRODUCT(('Matriz Criterios'!$H$6:$V$6="X")*ISNUMBER('Registro Notas'!$D6:$R6)*'Registro Notas'!$D6:$R6)/SUMPRODUCT(('Matriz Criterios'!$H$6:$V$6="X")*ISNUMBER('Registro Notas'!$D6:$R6))) | D6: =IF(SUMPRODUCT(('Matriz Criterios'!$H$7:$V$7="X")*ISNUMBER('Registro Notas'!$D6:$R6))=0, "-", SUMPRODUCT(('Matriz Criterios'!$H$7:$V$7="X")*ISNUMBER('Registro Notas'!$D6:$R6)*'Registro Notas'!$D6:$R6)/SUMPRODUCT(('Matriz Criterios'!$H$7:$V$7="X")*ISNUMBER('Registro Notas'!$D6:$R6))) | E6: =IF(SUMPRODUCT(('Matriz Criterios'!$H$8:$V$8="X")*ISNUMBER('Registro Notas'!$D6:$R6))=0, "-", SUMPRODUCT(('Matriz Criterios'!$H$8:$V$8="X")*ISNUMBER('Registro Notas'!$D6:$R6)*'Registro Notas'!$D6:$R6)/SUMPRODUCT(('Matriz Criterios'!$H$8:$V$8="X")*ISNUMBER('Registro Notas'!$D6:$R6))) | F6: =IF(SUMPRODUCT(('Matriz Criterios'!$H$9:$V$9="X")*ISNUMBER('Registro Notas'!$D6:$R6))=0, "-", SUMPRODUCT(('Matriz Criterios'!$H$9:$V$9="X")*ISNUMBER('Registro Notas'!$D6:$R6)*'Registro Notas'!$D6:$R6)/SUMPRODUCT(('Matriz Criterios'!$H$9:$V$9="X")*ISNUMBER('Registro Notas'!$D6:$R6))) | G6: =IF(SUMPRODUCT(('Matriz Criterios'!$H$10:$V$10="X")*ISNUMBER('Registro Notas'!$D6:$R6))=0, "-", SUMPRODUCT(('Matriz Criterios'!$H$10:$V$10="X")*ISNUMBER('Registro Notas'!$D6:$R6)*'Registro Notas'!$D6:$R6)/SUMPRODUCT(('Matriz Criterios'!$H$10:$V$10="X")*ISNUMBER('Registro Notas'!$D6:$R6))) | H6: =IF(SUMPRODUCT(('Matriz Criterios'!$H$11:$V$11="X")*ISNUMBER('Registro Notas'!$D6:$R6))=0, "-", SUMPRODUCT(('Matriz Criterios'!$H$11:$V$11="X")*ISNUMBER('Registro Notas'!$D6:$R6)*'Registro Notas'!$D6:$R6)/SUMPRODUCT(('Matriz Criterios'!$H$11:$V$11="X")*ISNUMBER('Registro Notas'!$D6:$R6))) | I6: =IF(SUMPRODUCT(('Matriz Criterios'!$H$12:$V$12="X")*ISNUMBER('Registro Notas'!$D6:$R6))=0, "-", SUMPRODUCT(('Matriz Criterios'!$H$12:$V$12="X")*ISNUMBER('Registro Notas'!$D6:$R6)*'Registro Notas'!$D6:$R6)/SUMPRODUCT(('Matriz Criterios'!$H$12:$V$12="X")*ISNUMBER('Registro Notas'!$D6:$R6))) | J6: =IF(SUMPRODUCT(('Matriz Criterios'!$H$13:$V$13="X")*ISNUMBER('Registro Notas'!$D6:$R6))=0, "-", SUMPRODUCT(('Matriz Criterios'!$H$13:$V$13="X")*ISNUMBER('Registro Notas'!$D6:$R6)*'Registro Notas'!$D6:$R6)/SUMPRODUCT(('Matriz Criterios'!$H$13:$V$13="X")*ISNUMBER('Registro Notas'!$D6:$R6))) | K6: =IF(SUMPRODUCT(('Matriz Criterios'!$H$14:$V$14="X")*ISNUMBER('Registro Notas'!$D6:$R6))=0, "-", SUMPRODUCT(('Matriz Criterios'!$H$14:$V$14="X")*ISNUMBER('Registro Notas'!$D6:$R6)*'Registro Notas'!$D6:$R6)/SUMPRODUCT(('Matriz Criterios'!$H$14:$V$14="X")*ISNUMBER('Registro Notas'!$D6:$R6))) | L6: =IF(SUMPRODUCT(('Matriz Criterios'!$H$15:$V$15="X")*ISNUMBER('Registro Notas'!$D6:$R6))=0, "-", SUMPRODUCT(('Matriz Criterios'!$H$15:$V$15="X")*ISNUMBER('Registro Notas'!$D6:$R6)*'Registro Notas'!$D6:$R6)/SUMPRODUCT(('Matriz Criterios'!$H$15:$V$15="X")*ISNUMBER('Registro Notas'!$D6:$R6))) | M6: =IF(SUMPRODUCT(('Matriz Criterios'!$H$16:$V$16="X")*ISNUMBER('Registro Notas'!$D6:$R6))=0, "-", SUMPRODUCT(('Matriz Criterios'!$H$16:$V$16="X")*ISNUMBER('Registro Notas'!$D6:$R6)*'Registro Notas'!$D6:$R6)/SUMPRODUCT(('Matriz Criterios'!$H$16:$V$16="X")*ISNUMBER('Registro Notas'!$D6:$R6))) | N6: =IF(SUMPRODUCT(('Matriz Criterios'!$H$17:$V$17="X")*ISNUMBER('Registro Notas'!$D6:$R6))=0, "-", SUMPRODUCT(('Matriz Criterios'!$H$17:$V$17="X")*ISNUMBER('Registro Notas'!$D6:$R6)*'Registro Notas'!$D6:$R6)/SUMPRODUCT(('Matriz Criterios'!$H$17:$V$17="X")*ISNUMBER('Registro Notas'!$D6:$R6))) | O6: =IF(SUMPRODUCT(('Matriz Criterios'!$H$18:$V$18="X")*ISNUMBER('Registro Notas'!$D6:$R6))=0, "-", SUMPRODUCT(('Matriz Criterios'!$H$18:$V$18="X")*ISNUMBER('Registro Notas'!$D6:$R6)*'Registro Notas'!$D6:$R6)/SUMPRODUCT(('Matriz Criterios'!$H$18:$V$18="X")*ISNUMBER('Registro Notas'!$D6:$R6))) | P6: =IF(SUMPRODUCT(('Matriz Criterios'!$H$19:$V$19="X")*ISNUMBER('Registro Notas'!$D6:$R6))=0, "-", SUMPRODUCT(('Matriz Criterios'!$H$19:$V$19="X")*ISNUMBER('Registro Notas'!$D6:$R6)*'Registro Notas'!$D6:$R6)/SUMPRODUCT(('Matriz Criterios'!$H$19:$V$19="X")*ISNUMBER('Registro Notas'!$D6:$R6))) | Q6: =IF(SUMPRODUCT(('Matriz Criterios'!$H$20:$V$20="X")*ISNUMBER('Registro Notas'!$D6:$R6))=0, "-", SUMPRODUCT(('Matriz Criterios'!$H$20:$V$20="X")*ISNUMBER('Registro Notas'!$D6:$R6)*'Registro Notas'!$D6:$R6)/SUMPRODUCT(('Matriz Criterios'!$H$20:$V$20="X")*ISNUMBER('Registro Notas'!$D6:$R6))) | R6: =IF(SUMPRODUCT(('Matriz Criterios'!$H$21:$V$21="X")*ISNUMBER('Registro Notas'!$D6:$R6))=0, "-", SUMPRODUCT(('Matriz Criterios'!$H$21:$V$21="X")*ISNUMBER('Registro Notas'!$D6:$R6)*'Registro Notas'!$D6:$R6)/SUMPRODUCT(('Matriz Criterios'!$H$21:$V$21="X")*ISNUMBER('Registro Notas'!$D6:$R6))) | S6: =IF(SUMPRODUCT(('Matriz Criterios'!$H$22:$V$22="X")*ISNUMBER('Registro Notas'!$D6:$R6))=0, "-", SUMPRODUCT(('Matriz Criterios'!$H$22:$V$22="X")*ISNUMBER('Registro Notas'!$D6:$R6)*'Registro Notas'!$D6:$R6)/SUMPRODUCT(('Matriz Criterios'!$H$22:$V$22="X")*ISNUMBER('Registro Notas'!$D6:$R6))) | T6: =IF(SUMPRODUCT(('Matriz Criterios'!$H$23:$V$23="X")*ISNUMBER('Registro Notas'!$D6:$R6))=0, "-", SUMPRODUCT(('Matriz Criterios'!$H$23:$V$23="X")*ISNUMBER('Registro Notas'!$D6:$R6)*'Registro Notas'!$D6:$R6)/SUMPRODUCT(('Matriz Criterios'!$H$23:$V$23="X")*ISNUMBER('Registro Notas'!$D6:$R6))) | U6: =IF(SUMPRODUCT(('Matriz Criterios'!$H$24:$V$24="X")*ISNUMBER('Registro Notas'!$D6:$R6))=0, "-", SUMPRODUCT(('Matriz Criterios'!$H$24:$V$24="X")*ISNUMBER('Registro Notas'!$D6:$R6)*'Registro Notas'!$D6:$R6)/SUMPRODUCT(('Matriz Criterios'!$H$24:$V$24="X")*ISNUMBER('Registro Notas'!$D6:$R6))) | V6: =IF(SUMPRODUCT(('Matriz Criterios'!$H$25:$V$25="X")*ISNUMBER('Registro Notas'!$D6:$R6))=0, "-", SUMPRODUCT(('Matriz Criterios'!$H$25:$V$25="X")*ISNUMBER('Registro Notas'!$D6:$R6)*'Registro Notas'!$D6:$R6)/SUMPRODUCT(('Matriz Criterios'!$H$25:$V$25="X")*ISNUMBER('Registro Notas'!$D6:$R6))) | W6: =IF(SUMPRODUCT(('Matriz Criterios'!$H$26:$V$26="X")*ISNUMBER('Registro Notas'!$D6:$R6))=0, "-", SUMPRODUCT(('Matriz Criterios'!$H$26:$V$26="X")*ISNUMBER('Registro Notas'!$D6:$R6)*'Registro Notas'!$D6:$R6)/SUMPRODUCT(('Matriz Criterios'!$H$26:$V$26="X")*ISNUMBER('Registro Notas'!$D6:$R6))) | X6: =IF(SUMPRODUCT(('Matriz Criterios'!$H$27:$V$27="X")*ISNUMBER('Registro Notas'!$D6:$R6))=0, "-", SUMPRODUCT(('Matriz Criterios'!$H$27:$V$27="X")*ISNUMBER('Registro Notas'!$D6:$R6)*'Registro Notas'!$D6:$R6)/SUMPRODUCT(('Matriz Criterios'!$H$27:$V$27="X")*ISNUMBER('Registro Notas'!$D6:$R6))) | Y6: =IF(SUMPRODUCT(('Matriz Criterios'!$H$28:$V$28="X")*ISNUMBER('Registro Notas'!$D6:$R6))=0, "-", SUMPRODUCT(('Matriz Criterios'!$H$28:$V$28="X")*ISNUMBER('Registro Notas'!$D6:$R6)*'Registro Notas'!$D6:$R6)/SUMPRODUCT(('Matriz Criterios'!$H$28:$V$28="X")*ISNUMBER('Registro Notas'!$D6:$R6))) | Z6: =IF(SUMPRODUCT(('Matriz Criterios'!$H$29:$V$29="X")*ISNUMBER('Registro Notas'!$D6:$R6))=0, "-", SUMPRODUCT(('Matriz Criterios'!$H$29:$V$29="X")*ISNUMBER('Registro Notas'!$D6:$R6)*'Registro Notas'!$D6:$R6)/SUMPRODUCT(('Matriz Criterios'!$H$29:$V$29="X")*ISNUMBER('Registro Notas'!$D6:$R6))) | AA6: =IF(SUMPRODUCT(('Matriz Criterios'!$H$30:$V$30="X")*ISNUMBER('Registro Notas'!$D6:$R6))=0, "-", SUMPRODUCT(('Matriz Criterios'!$H$30:$V$30="X")*ISNUMBER('Registro Notas'!$D6:$R6)*'Registro Notas'!$D6:$R6)/SUMPRODUCT(('Matriz Criterios'!$H$30:$V$30="X")*ISNUMBER('Registro Notas'!$D6:$R6))) | AB6: =IF(SUMPRODUCT(('Matriz Criterios'!$H$31:$V$31="X")*ISNUMBER('Registro Notas'!$D6:$R6))=0, "-", SUMPRODUCT(('Matriz Criterios'!$H$31:$V$31="X")*ISNUMBER('Registro Notas'!$D6:$R6)*'Registro Notas'!$D6:$R6)/SUMPRODUCT(('Matriz Criterios'!$H$31:$V$31="X")*ISNUMBER('Registro Notas'!$D6:$R6))) | AC6: =IF(SUMPRODUCT(('Matriz Criterios'!$H$32:$V$32="X")*ISNUMBER('Registro Notas'!$D6:$R6))=0, "-", SUMPRODUCT(('Matriz Criterios'!$H$32:$V$32="X")*ISNUMBER('Registro Notas'!$D6:$R6)*'Registro Notas'!$D6:$R6)/SUMPRODUCT(('Matriz Criterios'!$H$32:$V$32="X")*ISNUMBER('Registro Notas'!$D6:$R6))) | AD6: =IF(SUMPRODUCT(('Matriz Criterios'!$H$33:$V$33="X")*ISNUMBER('Registro Notas'!$D6:$R6))=0, "-", SUMPRODUCT(('Matriz Criterios'!$H$33:$V$33="X")*ISNUMBER('Registro Notas'!$D6:$R6)*'Registro Notas'!$D6:$R6)/SUMPRODUCT(('Matriz Criterios'!$H$33:$V$33="X")*ISNUMBER('Registro Notas'!$D6:$R6))) | AE6: =IF(SUMPRODUCT(('Matriz Criterios'!$H$34:$V$34="X")*ISNUMBER('Registro Notas'!$D6:$R6))=0, "-", SUMPRODUCT(('Matriz Criterios'!$H$34:$V$34="X")*ISNUMBER('Registro Notas'!$D6:$R6)*'Registro Notas'!$D6:$R6)/SUMPRODUCT(('Matriz Criterios'!$H$34:$V$34="X")*ISNUMBER('Registro Notas'!$D6:$R6))) | AF6: =IF(SUMPRODUCT(('Matriz Criterios'!$H$35:$V$35="X")*ISNUMBER('Registro Notas'!$D6:$R6))=0, "-", SUMPRODUCT(('Matriz Criterios'!$H$35:$V$35="X")*ISNUMBER('Registro Notas'!$D6:$R6)*'Registro Notas'!$D6:$R6)/SUMPRODUCT(('Matriz Criterios'!$H$35:$V$35="X")*ISNUMBER('Registro Notas'!$D6:$R6))) | AG6: =IF(SUMPRODUCT(('Matriz Criterios'!$H$36:$V$36="X")*ISNUMBER('Registro Notas'!$D6:$R6))=0, "-", SUMPRODUCT(('Matriz Criterios'!$H$36:$V$36="X")*ISNUMBER('Registro Notas'!$D6:$R6)*'Registro Notas'!$D6:$R6)/SUMPRODUCT(('Matriz Criterios'!$H$36:$V$36="X")*ISNUMBER('Registro Notas'!$D6:$R6))) | AH6: =IF(SUMPRODUCT(('Matriz Criterios'!$H$37:$V$37="X")*ISNUMBER('Registro Notas'!$D6:$R6))=0, "-", SUMPRODUCT(('Matriz Criterios'!$H$37:$V$37="X")*ISNUMBER('Registro Notas'!$D6:$R6)*'Registro Notas'!$D6:$R6)/SUMPRODUCT(('Matriz Criterios'!$H$37:$V$37="X")*ISNUMBER('Registro Notas'!$D6:$R6))) | AI6: =IF(SUMPRODUCT(('Matriz Criterios'!$H$38:$V$38="X")*ISNUMBER('Registro Notas'!$D6:$R6))=0, "-", SUMPRODUCT(('Matriz Criterios'!$H$38:$V$38="X")*ISNUMBER('Registro Notas'!$D6:$R6)*'Registro Notas'!$D6:$R6)/SUMPRODUCT(('Matriz Criterios'!$H$38:$V$38="X")*ISNUMBER('Registro Notas'!$D6:$R6))) | AJ6: =IF(SUMPRODUCT(('Matriz Criterios'!$H$39:$V$39="X")*ISNUMBER('Registro Notas'!$D6:$R6))=0, "-", SUMPRODUCT(('Matriz Criterios'!$H$39:$V$39="X")*ISNUMBER('Registro Notas'!$D6:$R6)*'Registro Notas'!$D6:$R6)/SUMPRODUCT(('Matriz Criterios'!$H$39:$V$39="X")*ISNUMBER('Registro Notas'!$D6:$R6))) | AK6: =IF(SUMPRODUCT(('Matriz Criterios'!$H$40:$V$40="X")*ISNUMBER('Registro Notas'!$D6:$R6))=0, "-", SUMPRODUCT(('Matriz Criterios'!$H$40:$V$40="X")*ISNUMBER('Registro Notas'!$D6:$R6)*'Registro Notas'!$D6:$R6)/SUMPRODUCT(('Matriz Criterios'!$H$40:$V$40="X")*ISNUMBER('Registro Notas'!$D6:$R6))) | AL6: =IF(SUMPRODUCT(('Matriz Criterios'!$H$41:$V$41="X")*ISNUMBER('Registro Notas'!$D6:$R6))=0, "-", SUMPRODUCT(('Matriz Criterios'!$H$41:$V$41="X")*ISNUMBER('Registro Notas'!$D6:$R6)*'Registro Notas'!$D6:$R6)/SUMPRODUCT(('Matriz Criterios'!$H$41:$V$41="X")*ISNUMBER('Registro Notas'!$D6:$R6))) | AM6: =IF(SUMPRODUCT(('Matriz Criterios'!$H$42:$V$42="X")*ISNUMBER('Registro Notas'!$D6:$R6))=0, "-", SUMPRODUCT(('Matriz Criterios'!$H$42:$V$42="X")*ISNUMBER('Registro Notas'!$D6:$R6)*'Registro Notas'!$D6:$R6)/SUMPRODUCT(('Matriz Criterios'!$H$42:$V$42="X")*ISNUMBER('Registro Notas'!$D6:$R6))) | AN6: =IF(SUMPRODUCT(('Matriz Criterios'!$H$43:$V$43="X")*ISNUMBER('Registro Notas'!$D6:$R6))=0, "-", SUMPRODUCT(('Matriz Criterios'!$H$43:$V$43="X")*ISNUMBER('Registro Notas'!$D6:$R6)*'Registro Notas'!$D6:$R6)/SUMPRODUCT(('Matriz Criterios'!$H$43:$V$43="X")*ISNUMBER('Registro Notas'!$D6:$R6))) | AO6: =IF(SUMPRODUCT(('Matriz Criterios'!$H$44:$V$44="X")*ISNUMBER('Registro Notas'!$D6:$R6))=0, "-", SUMPRODUCT(('Matriz Criterios'!$H$44:$V$44="X")*ISNUMBER('Registro Notas'!$D6:$R6)*'Registro Notas'!$D6:$R6)/SUMPRODUCT(('Matriz Criterios'!$H$44:$V$44="X")*ISNUMBER('Registro Notas'!$D6:$R6))) | AP6: =IF(SUMPRODUCT(('Matriz Criterios'!$H$45:$V$45="X")*ISNUMBER('Registro Notas'!$D6:$R6))=0, "-", SUMPRODUCT(('Matriz Criterios'!$H$45:$V$45="X")*ISNUMBER('Registro Notas'!$D6:$R6)*'Registro Notas'!$D6:$R6)/SUMPRODUCT(('Matriz Criterios'!$H$45:$V$45="X")*ISNUMBER('Registro Notas'!$D6:$R6))) | AQ6: =AVERAGE(C6:AP6) | AR6: =COUNTIF(C6:AP6, ">=5")
A7: 2 | B7: Benítez Romero, Carlos | C7: =IF(SUMPRODUCT(('Matriz Criterios'!$H$6:$V$6="X")*ISNUMBER('Registro Notas'!$D7:$R7))=0, "-", SUMPRODUCT(('Matriz Criterios'!$H$6:$V$6="X")*ISNUMBER('Registro Notas'!$D7:$R7)*'Registro Notas'!$D7:$R7)/SUMPRODUCT(('Matriz Criterios'!$H$6:$V$6="X")*ISNUMBER('Registro Notas'!$D7:$R7))) | D7: =IF(SUMPRODUCT(('Matriz Criterios'!$H$7:$V$7="X")*ISNUMBER('Registro Notas'!$D7:$R7))=0, "-", SUMPRODUCT(('Matriz Criterios'!$H$7:$V$7="X")*ISNUMBER('Registro Notas'!$D7:$R7)*'Registro Notas'!$D7:$R7)/SUMPRODUCT(('Matriz Criterios'!$H$7:$V$7="X")*ISNUMBER('Registro Notas'!$D7:$R7))) | E7: =IF(SUMPRODUCT(('Matriz Criterios'!$H$8:$V$8="X")*ISNUMBER('Registro Notas'!$D7:$R7))=0, "-", SUMPRODUCT(('Matriz Criterios'!$H$8:$V$8="X")*ISNUMBER('Registro Notas'!$D7:$R7)*'Registro Notas'!$D7:$R7)/SUMPRODUCT(('Matriz Criterios'!$H$8:$V$8="X")*ISNUMBER('Registro Notas'!$D7:$R7))) | F7: =IF(SUMPRODUCT(('Matriz Criterios'!$H$9:$V$9="X")*ISNUMBER('Registro Notas'!$D7:$R7))=0, "-", SUMPRODUCT(('Matriz Criterios'!$H$9:$V$9="X")*ISNUMBER('Registro Notas'!$D7:$R7)*'Registro Notas'!$D7:$R7)/SUMPRODUCT(('Matriz Criterios'!$H$9:$V$9="X")*ISNUMBER('Registro Notas'!$D7:$R7))) | G7: =IF(SUMPRODUCT(('Matriz Criterios'!$H$10:$V$10="X")*ISNUMBER('Registro Notas'!$D7:$R7))=0, "-", SUMPRODUCT(('Matriz Criterios'!$H$10:$V$10="X")*ISNUMBER('Registro Notas'!$D7:$R7)*'Registro Notas'!$D7:$R7)/SUMPRODUCT(('Matriz Criterios'!$H$10:$V$10="X")*ISNUMBER('Registro Notas'!$D7:$R7))) | H7: =IF(SUMPRODUCT(('Matriz Criterios'!$H$11:$V$11="X")*ISNUMBER('Registro Notas'!$D7:$R7))=0, "-", SUMPRODUCT(('Matriz Criterios'!$H$11:$V$11="X")*ISNUMBER('Registro Notas'!$D7:$R7)*'Registro Notas'!$D7:$R7)/SUMPRODUCT(('Matriz Criterios'!$H$11:$V$11="X")*ISNUMBER('Registro Notas'!$D7:$R7))) | I7: =IF(SUMPRODUCT(('Matriz Criterios'!$H$12:$V$12="X")*ISNUMBER('Registro Notas'!$D7:$R7))=0, "-", SUMPRODUCT(('Matriz Criterios'!$H$12:$V$12="X")*ISNUMBER('Registro Notas'!$D7:$R7)*'Registro Notas'!$D7:$R7)/SUMPRODUCT(('Matriz Criterios'!$H$12:$V$12="X")*ISNUMBER('Registro Notas'!$D7:$R7))) | J7: =IF(SUMPRODUCT(('Matriz Criterios'!$H$13:$V$13="X")*ISNUMBER('Registro Notas'!$D7:$R7))=0, "-", SUMPRODUCT(('Matriz Criterios'!$H$13:$V$13="X")*ISNUMBER('Registro Notas'!$D7:$R7)*'Registro Notas'!$D7:$R7)/SUMPRODUCT(('Matriz Criterios'!$H$13:$V$13="X")*ISNUMBER('Registro Notas'!$D7:$R7))) | K7: =IF(SUMPRODUCT(('Matriz Criterios'!$H$14:$V$14="X")*ISNUMBER('Registro Notas'!$D7:$R7))=0, "-", SUMPRODUCT(('Matriz Criterios'!$H$14:$V$14="X")*ISNUMBER('Registro Notas'!$D7:$R7)*'Registro Notas'!$D7:$R7)/SUMPRODUCT(('Matriz Criterios'!$H$14:$V$14="X")*ISNUMBER('Registro Notas'!$D7:$R7))) | L7: =IF(SUMPRODUCT(('Matriz Criterios'!$H$15:$V$15="X")*ISNUMBER('Registro Notas'!$D7:$R7))=0, "-", SUMPRODUCT(('Matriz Criterios'!$H$15:$V$15="X")*ISNUMBER('Registro Notas'!$D7:$R7)*'Registro Notas'!$D7:$R7)/SUMPRODUCT(('Matriz Criterios'!$H$15:$V$15="X")*ISNUMBER('Registro Notas'!$D7:$R7))) | M7: =IF(SUMPRODUCT(('Matriz Criterios'!$H$16:$V$16="X")*ISNUMBER('Registro Notas'!$D7:$R7))=0, "-", SUMPRODUCT(('Matriz Criterios'!$H$16:$V$16="X")*ISNUMBER('Registro Notas'!$D7:$R7)*'Registro Notas'!$D7:$R7)/SUMPRODUCT(('Matriz Criterios'!$H$16:$V$16="X")*ISNUMBER('Registro Notas'!$D7:$R7))) | N7: =IF(SUMPRODUCT(('Matriz Criterios'!$H$17:$V$17="X")*ISNUMBER('Registro Notas'!$D7:$R7))=0, "-", SUMPRODUCT(('Matriz Criterios'!$H$17:$V$17="X")*ISNUMBER('Registro Notas'!$D7:$R7)*'Registro Notas'!$D7:$R7)/SUMPRODUCT(('Matriz Criterios'!$H$17:$V$17="X")*ISNUMBER('Registro Notas'!$D7:$R7))) | O7: =IF(SUMPRODUCT(('Matriz Criterios'!$H$18:$V$18="X")*ISNUMBER('Registro Notas'!$D7:$R7))=0, "-", SUMPRODUCT(('Matriz Criterios'!$H$18:$V$18="X")*ISNUMBER('Registro Notas'!$D7:$R7)*'Registro Notas'!$D7:$R7)/SUMPRODUCT(('Matriz Criterios'!$H$18:$V$18="X")*ISNUMBER('Registro Notas'!$D7:$R7))) | P7: =IF(SUMPRODUCT(('Matriz Criterios'!$H$19:$V$19="X")*ISNUMBER('Registro Notas'!$D7:$R7))=0, "-", SUMPRODUCT(('Matriz Criterios'!$H$19:$V$19="X")*ISNUMBER('Registro Notas'!$D7:$R7)*'Registro Notas'!$D7:$R7)/SUMPRODUCT(('Matriz Criterios'!$H$19:$V$19="X")*ISNUMBER('Registro Notas'!$D7:$R7))) | Q7: =IF(SUMPRODUCT(('Matriz Criterios'!$H$20:$V$20="X")*ISNUMBER('Registro Notas'!$D7:$R7))=0, "-", SUMPRODUCT(('Matriz Criterios'!$H$20:$V$20="X")*ISNUMBER('Registro Notas'!$D7:$R7)*'Registro Notas'!$D7:$R7)/SUMPRODUCT(('Matriz Criterios'!$H$20:$V$20="X")*ISNUMBER('Registro Notas'!$D7:$R7))) | R7: =IF(SUMPRODUCT(('Matriz Criterios'!$H$21:$V$21="X")*ISNUMBER('Registro Notas'!$D7:$R7))=0, "-", SUMPRODUCT(('Matriz Criterios'!$H$21:$V$21="X")*ISNUMBER('Registro Notas'!$D7:$R7)*'Registro Notas'!$D7:$R7)/SUMPRODUCT(('Matriz Criterios'!$H$21:$V$21="X")*ISNUMBER('Registro Notas'!$D7:$R7))) | S7: =IF(SUMPRODUCT(('Matriz Criterios'!$H$22:$V$22="X")*ISNUMBER('Registro Notas'!$D7:$R7))=0, "-", SUMPRODUCT(('Matriz Criterios'!$H$22:$V$22="X")*ISNUMBER('Registro Notas'!$D7:$R7)*'Registro Notas'!$D7:$R7)/SUMPRODUCT(('Matriz Criterios'!$H$22:$V$22="X")*ISNUMBER('Registro Notas'!$D7:$R7))) | T7: =IF(SUMPRODUCT(('Matriz Criterios'!$H$23:$V$23="X")*ISNUMBER('Registro Notas'!$D7:$R7))=0, "-", SUMPRODUCT(('Matriz Criterios'!$H$23:$V$23="X")*ISNUMBER('Registro Notas'!$D7:$R7)*'Registro Notas'!$D7:$R7)/SUMPRODUCT(('Matriz Criterios'!$H$23:$V$23="X")*ISNUMBER('Registro Notas'!$D7:$R7))) | U7: =IF(SUMPRODUCT(('Matriz Criterios'!$H$24:$V$24="X")*ISNUMBER('Registro Notas'!$D7:$R7))=0, "-", SUMPRODUCT(('Matriz Criterios'!$H$24:$V$24="X")*ISNUMBER('Registro Notas'!$D7:$R7)*'Registro Notas'!$D7:$R7)/SUMPRODUCT(('Matriz Criterios'!$H$24:$V$24="X")*ISNUMBER('Registro Notas'!$D7:$R7))) | V7: =IF(SUMPRODUCT(('Matriz Criterios'!$H$25:$V$25="X")*ISNUMBER('Registro Notas'!$D7:$R7))=0, "-", SUMPRODUCT(('Matriz Criterios'!$H$25:$V$25="X")*ISNUMBER('Registro Notas'!$D7:$R7)*'Registro Notas'!$D7:$R7)/SUMPRODUCT(('Matriz Criterios'!$H$25:$V$25="X")*ISNUMBER('Registro Notas'!$D7:$R7))) | W7: =IF(SUMPRODUCT(('Matriz Criterios'!$H$26:$V$26="X")*ISNUMBER('Registro Notas'!$D7:$R7))=0, "-", SUMPRODUCT(('Matriz Criterios'!$H$26:$V$26="X")*ISNUMBER('Registro Notas'!$D7:$R7)*'Registro Notas'!$D7:$R7)/SUMPRODUCT(('Matriz Criterios'!$H$26:$V$26="X")*ISNUMBER('Registro Notas'!$D7:$R7))) | X7: =IF(SUMPRODUCT(('Matriz Criterios'!$H$27:$V$27="X")*ISNUMBER('Registro Notas'!$D7:$R7))=0, "-", SUMPRODUCT(('Matriz Criterios'!$H$27:$V$27="X")*ISNUMBER('Registro Notas'!$D7:$R7)*'Registro Notas'!$D7:$R7)/SUMPRODUCT(('Matriz Criterios'!$H$27:$V$27="X")*ISNUMBER('Registro Notas'!$D7:$R7))) | Y7: =IF(SUMPRODUCT(('Matriz Criterios'!$H$28:$V$28="X")*ISNUMBER('Registro Notas'!$D7:$R7))=0, "-", SUMPRODUCT(('Matriz Criterios'!$H$28:$V$28="X")*ISNUMBER('Registro Notas'!$D7:$R7)*'Registro Notas'!$D7:$R7)/SUMPRODUCT(('Matriz Criterios'!$H$28:$V$28="X")*ISNUMBER('Registro Notas'!$D7:$R7))) | Z7: =IF(SUMPRODUCT(('Matriz Criterios'!$H$29:$V$29="X")*ISNUMBER('Registro Notas'!$D7:$R7))=0, "-", SUMPRODUCT(('Matriz Criterios'!$H$29:$V$29="X")*ISNUMBER('Registro Notas'!$D7:$R7)*'Registro Notas'!$D7:$R7)/SUMPRODUCT(('Matriz Criterios'!$H$29:$V$29="X")*ISNUMBER('Registro Notas'!$D7:$R7))) | AA7: =IF(SUMPRODUCT(('Matriz Criterios'!$H$30:$V$30="X")*ISNUMBER('Registro Notas'!$D7:$R7))=0, "-", SUMPRODUCT(('Matriz Criterios'!$H$30:$V$30="X")*ISNUMBER('Registro Notas'!$D7:$R7)*'Registro Notas'!$D7:$R7)/SUMPRODUCT(('Matriz Criterios'!$H$30:$V$30="X")*ISNUMBER('Registro Notas'!$D7:$R7))) | AB7: =IF(SUMPRODUCT(('Matriz Criterios'!$H$31:$V$31="X")*ISNUMBER('Registro Notas'!$D7:$R7))=0, "-", SUMPRODUCT(('Matriz Criterios'!$H$31:$V$31="X")*ISNUMBER('Registro Notas'!$D7:$R7)*'Registro Notas'!$D7:$R7)/SUMPRODUCT(('Matriz Criterios'!$H$31:$V$31="X")*ISNUMBER('Registro Notas'!$D7:$R7))) | AC7: =IF(SUMPRODUCT(('Matriz Criterios'!$H$32:$V$32="X")*ISNUMBER('Registro Notas'!$D7:$R7))=0, "-", SUMPRODUCT(('Matriz Criterios'!$H$32:$V$32="X")*ISNUMBER('Registro Notas'!$D7:$R7)*'Registro Notas'!$D7:$R7)/SUMPRODUCT(('Matriz Criterios'!$H$32:$V$32="X")*ISNUMBER('Registro Notas'!$D7:$R7))) | AD7: =IF(SUMPRODUCT(('Matriz Criterios'!$H$33:$V$33="X")*ISNUMBER('Registro Notas'!$D7:$R7))=0, "-", SUMPRODUCT(('Matriz Criterios'!$H$33:$V$33="X")*ISNUMBER('Registro Notas'!$D7:$R7)*'Registro Notas'!$D7:$R7)/SUMPRODUCT(('Matriz Criterios'!$H$33:$V$33="X")*ISNUMBER('Registro Notas'!$D7:$R7))) | AE7: =IF(SUMPRODUCT(('Matriz Criterios'!$H$34:$V$34="X")*ISNUMBER('Registro Notas'!$D7:$R7))=0, "-", SUMPRODUCT(('Matriz Criterios'!$H$34:$V$34="X")*ISNUMBER('Registro Notas'!$D7:$R7)*'Registro Notas'!$D7:$R7)/SUMPRODUCT(('Matriz Criterios'!$H$34:$V$34="X")*ISNUMBER('Registro Notas'!$D7:$R7))) | AF7: =IF(SUMPRODUCT(('Matriz Criterios'!$H$35:$V$35="X")*ISNUMBER('Registro Notas'!$D7:$R7))=0, "-", SUMPRODUCT(('Matriz Criterios'!$H$35:$V$35="X")*ISNUMBER('Registro Notas'!$D7:$R7)*'Registro Notas'!$D7:$R7)/SUMPRODUCT(('Matriz Criterios'!$H$35:$V$35="X")*ISNUMBER('Registro Notas'!$D7:$R7))) | AG7: =IF(SUMPRODUCT(('Matriz Criterios'!$H$36:$V$36="X")*ISNUMBER('Registro Notas'!$D7:$R7))=0, "-", SUMPRODUCT(('Matriz Criterios'!$H$36:$V$36="X")*ISNUMBER('Registro Notas'!$D7:$R7)*'Registro Notas'!$D7:$R7)/SUMPRODUCT(('Matriz Criterios'!$H$36:$V$36="X")*ISNUMBER('Registro Notas'!$D7:$R7))) | AH7: =IF(SUMPRODUCT(('Matriz Criterios'!$H$37:$V$37="X")*ISNUMBER('Registro Notas'!$D7:$R7))=0, "-", SUMPRODUCT(('Matriz Criterios'!$H$37:$V$37="X")*ISNUMBER('Registro Notas'!$D7:$R7)*'Registro Notas'!$D7:$R7)/SUMPRODUCT(('Matriz Criterios'!$H$37:$V$37="X")*ISNUMBER('Registro Notas'!$D7:$R7))) | AI7: =IF(SUMPRODUCT(('Matriz Criterios'!$H$38:$V$38="X")*ISNUMBER('Registro Notas'!$D7:$R7))=0, "-", SUMPRODUCT(('Matriz Criterios'!$H$38:$V$38="X")*ISNUMBER('Registro Notas'!$D7:$R7)*'Registro Notas'!$D7:$R7)/SUMPRODUCT(('Matriz Criterios'!$H$38:$V$38="X")*ISNUMBER('Registro Notas'!$D7:$R7))) | AJ7: =IF(SUMPRODUCT(('Matriz Criterios'!$H$39:$V$39="X")*ISNUMBER('Registro Notas'!$D7:$R7))=0, "-", SUMPRODUCT(('Matriz Criterios'!$H$39:$V$39="X")*ISNUMBER('Registro Notas'!$D7:$R7)*'Registro Notas'!$D7:$R7)/SUMPRODUCT(('Matriz Criterios'!$H$39:$V$39="X")*ISNUMBER('Registro Notas'!$D7:$R7))) | AK7: =IF(SUMPRODUCT(('Matriz Criterios'!$H$40:$V$40="X")*ISNUMBER('Registro Notas'!$D7:$R7))=0, "-", SUMPRODUCT(('Matriz Criterios'!$H$40:$V$40="X")*ISNUMBER('Registro Notas'!$D7:$R7)*'Registro Notas'!$D7:$R7)/SUMPRODUCT(('Matriz Criterios'!$H$40:$V$40="X")*ISNUMBER('Registro Notas'!$D7:$R7))) | AL7: =IF(SUMPRODUCT(('Matriz Criterios'!$H$41:$V$41="X")*ISNUMBER('Registro Notas'!$D7:$R7))=0, "-", SUMPRODUCT(('Matriz Criterios'!$H$41:$V$41="X")*ISNUMBER('Registro Notas'!$D7:$R7)*'Registro Notas'!$D7:$R7)/SUMPRODUCT(('Matriz Criterios'!$H$41:$V$41="X")*ISNUMBER('Registro Notas'!$D7:$R7))) | AM7: =IF(SUMPRODUCT(('Matriz Criterios'!$H$42:$V$42="X")*ISNUMBER('Registro Notas'!$D7:$R7))=0, "-", SUMPRODUCT(('Matriz Criterios'!$H$42:$V$42="X")*ISNUMBER('Registro Notas'!$D7:$R7)*'Registro Notas'!$D7:$R7)/SUMPRODUCT(('Matriz Criterios'!$H$42:$V$42="X")*ISNUMBER('Registro Notas'!$D7:$R7))) | AN7: =IF(SUMPRODUCT(('Matriz Criterios'!$H$43:$V$43="X")*ISNUMBER('Registro Notas'!$D7:$R7))=0, "-", SUMPRODUCT(('Matriz Criterios'!$H$43:$V$43="X")*ISNUMBER('Registro Notas'!$D7:$R7)*'Registro Notas'!$D7:$R7)/SUMPRODUCT(('Matriz Criterios'!$H$43:$V$43="X")*ISNUMBER('Registro Notas'!$D7:$R7))) | AO7: =IF(SUMPRODUCT(('Matriz Criterios'!$H$44:$V$44="X")*ISNUMBER('Registro Notas'!$D7:$R7))=0, "-", SUMPRODUCT(('Matriz Criterios'!$H$44:$V$44="X")*ISNUMBER('Registro Notas'!$D7:$R7)*'Registro Notas'!$D7:$R7)/SUMPRODUCT(('Matriz Criterios'!$H$44:$V$44="X")*ISNUMBER('Registro Notas'!$D7:$R7))) | AP7: =IF(SUMPRODUCT(('Matriz Criterios'!$H$45:$V$45="X")*ISNUMBER('Registro Notas'!$D7:$R7))=0, "-", SUMPRODUCT(('Matriz Criterios'!$H$45:$V$45="X")*ISNUMBER('Registro Notas'!$D7:$R7)*'Registro Notas'!$D7:$R7)/SUMPRODUCT(('Matriz Criterios'!$H$45:$V$45="X")*ISNUMBER('Registro Notas'!$D7:$R7))) | AQ7: =AVERAGE(C7:AP7) | AR7: =COUNTIF(C7:AP7, ">=5")
A8: 3 | B8: Castillo Morales, Elena | C8: =IF(SUMPRODUCT(('Matriz Criterios'!$H$6:$V$6="X")*ISNUMBER('Registro Notas'!$D8:$R8))=0, "-", SUMPRODUCT(('Matriz Criterios'!$H$6:$V$6="X")*ISNUMBER('Registro Notas'!$D8:$R8)*'Registro Notas'!$D8:$R8)/SUMPRODUCT(('Matriz Criterios'!$H$6:$V$6="X")*ISNUMBER('Registro Notas'!$D8:$R8))) | D8: =IF(SUMPRODUCT(('Matriz Criterios'!$H$7:$V$7="X")*ISNUMBER('Registro Notas'!$D8:$R8))=0, "-", SUMPRODUCT(('Matriz Criterios'!$H$7:$V$7="X")*ISNUMBER('Registro Notas'!$D8:$R8)*'Registro Notas'!$D8:$R8)/SUMPRODUCT(('Matriz Criterios'!$H$7:$V$7="X")*ISNUMBER('Registro Notas'!$D8:$R8))) | E8: =IF(SUMPRODUCT(('Matriz Criterios'!$H$8:$V$8="X")*ISNUMBER('Registro Notas'!$D8:$R8))=0, "-", SUMPRODUCT(('Matriz Criterios'!$H$8:$V$8="X")*ISNUMBER('Registro Notas'!$D8:$R8)*'Registro Notas'!$D8:$R8)/SUMPRODUCT(('Matriz Criterios'!$H$8:$V$8="X")*ISNUMBER('Registro Notas'!$D8:$R8))) | F8: =IF(SUMPRODUCT(('Matriz Criterios'!$H$9:$V$9="X")*ISNUMBER('Registro Notas'!$D8:$R8))=0, "-", SUMPRODUCT(('Matriz Criterios'!$H$9:$V$9="X")*ISNUMBER('Registro Notas'!$D8:$R8)*'Registro Notas'!$D8:$R8)/SUMPRODUCT(('Matriz Criterios'!$H$9:$V$9="X")*ISNUMBER('Registro Notas'!$D8:$R8))) | G8: =IF(SUMPRODUCT(('Matriz Criterios'!$H$10:$V$10="X")*ISNUMBER('Registro Notas'!$D8:$R8))=0, "-", SUMPRODUCT(('Matriz Criterios'!$H$10:$V$10="X")*ISNUMBER('Registro Notas'!$D8:$R8)*'Registro Notas'!$D8:$R8)/SUMPRODUCT(('Matriz Criterios'!$H$10:$V$10="X")*ISNUMBER('Registro Notas'!$D8:$R8))) | H8: =IF(SUMPRODUCT(('Matriz Criterios'!$H$11:$V$11="X")*ISNUMBER('Registro Notas'!$D8:$R8))=0, "-", SUMPRODUCT(('Matriz Criterios'!$H$11:$V$11="X")*ISNUMBER('Registro Notas'!$D8:$R8)*'Registro Notas'!$D8:$R8)/SUMPRODUCT(('Matriz Criterios'!$H$11:$V$11="X")*ISNUMBER('Registro Notas'!$D8:$R8))) | I8: =IF(SUMPRODUCT(('Matriz Criterios'!$H$12:$V$12="X")*ISNUMBER('Registro Notas'!$D8:$R8))=0, "-", SUMPRODUCT(('Matriz Criterios'!$H$12:$V$12="X")*ISNUMBER('Registro Notas'!$D8:$R8)*'Registro Notas'!$D8:$R8)/SUMPRODUCT(('Matriz Criterios'!$H$12:$V$12="X")*ISNUMBER('Registro Notas'!$D8:$R8))) | J8: =IF(SUMPRODUCT(('Matriz Criterios'!$H$13:$V$13="X")*ISNUMBER('Registro Notas'!$D8:$R8))=0, "-", SUMPRODUCT(('Matriz Criterios'!$H$13:$V$13="X")*ISNUMBER('Registro Notas'!$D8:$R8)*'Registro Notas'!$D8:$R8)/SUMPRODUCT(('Matriz Criterios'!$H$13:$V$13="X")*ISNUMBER('Registro Notas'!$D8:$R8))) | K8: =IF(SUMPRODUCT(('Matriz Criterios'!$H$14:$V$14="X")*ISNUMBER('Registro Notas'!$D8:$R8))=0, "-", SUMPRODUCT(('Matriz Criterios'!$H$14:$V$14="X")*ISNUMBER('Registro Notas'!$D8:$R8)*'Registro Notas'!$D8:$R8)/SUMPRODUCT(('Matriz Criterios'!$H$14:$V$14="X")*ISNUMBER('Registro Notas'!$D8:$R8))) | L8: =IF(SUMPRODUCT(('Matriz Criterios'!$H$15:$V$15="X")*ISNUMBER('Registro Notas'!$D8:$R8))=0, "-", SUMPRODUCT(('Matriz Criterios'!$H$15:$V$15="X")*ISNUMBER('Registro Notas'!$D8:$R8)*'Registro Notas'!$D8:$R8)/SUMPRODUCT(('Matriz Criterios'!$H$15:$V$15="X")*ISNUMBER('Registro Notas'!$D8:$R8))) | M8: =IF(SUMPRODUCT(('Matriz Criterios'!$H$16:$V$16="X")*ISNUMBER('Registro Notas'!$D8:$R8))=0, "-", SUMPRODUCT(('Matriz Criterios'!$H$16:$V$16="X")*ISNUMBER('Registro Notas'!$D8:$R8)*'Registro Notas'!$D8:$R8)/SUMPRODUCT(('Matriz Criterios'!$H$16:$V$16="X")*ISNUMBER('Registro Notas'!$D8:$R8))) | N8: =IF(SUMPRODUCT(('Matriz Criterios'!$H$17:$V$17="X")*ISNUMBER('Registro Notas'!$D8:$R8))=0, "-", SUMPRODUCT(('Matriz Criterios'!$H$17:$V$17="X")*ISNUMBER('Registro Notas'!$D8:$R8)*'Registro Notas'!$D8:$R8)/SUMPRODUCT(('Matriz Criterios'!$H$17:$V$17="X")*ISNUMBER('Registro Notas'!$D8:$R8))) | O8: =IF(SUMPRODUCT(('Matriz Criterios'!$H$18:$V$18="X")*ISNUMBER('Registro Notas'!$D8:$R8))=0, "-", SUMPRODUCT(('Matriz Criterios'!$H$18:$V$18="X")*ISNUMBER('Registro Notas'!$D8:$R8)*'Registro Notas'!$D8:$R8)/SUMPRODUCT(('Matriz Criterios'!$H$18:$V$18="X")*ISNUMBER('Registro Notas'!$D8:$R8))) | P8: =IF(SUMPRODUCT(('Matriz Criterios'!$H$19:$V$19="X")*ISNUMBER('Registro Notas'!$D8:$R8))=0, "-", SUMPRODUCT(('Matriz Criterios'!$H$19:$V$19="X")*ISNUMBER('Registro Notas'!$D8:$R8)*'Registro Notas'!$D8:$R8)/SUMPRODUCT(('Matriz Criterios'!$H$19:$V$19="X")*ISNUMBER('Registro Notas'!$D8:$R8))) | Q8: =IF(SUMPRODUCT(('Matriz Criterios'!$H$20:$V$20="X")*ISNUMBER('Registro Notas'!$D8:$R8))=0, "-", SUMPRODUCT(('Matriz Criterios'!$H$20:$V$20="X")*ISNUMBER('Registro Notas'!$D8:$R8)*'Registro Notas'!$D8:$R8)/SUMPRODUCT(('Matriz Criterios'!$H$20:$V$20="X")*ISNUMBER('Registro Notas'!$D8:$R8))) | R8: =IF(SUMPRODUCT(('Matriz Criterios'!$H$21:$V$21="X")*ISNUMBER('Registro Notas'!$D8:$R8))=0, "-", SUMPRODUCT(('Matriz Criterios'!$H$21:$V$21="X")*ISNUMBER('Registro Notas'!$D8:$R8)*'Registro Notas'!$D8:$R8)/SUMPRODUCT(('Matriz Criterios'!$H$21:$V$21="X")*ISNUMBER('Registro Notas'!$D8:$R8))) | S8: =IF(SUMPRODUCT(('Matriz Criterios'!$H$22:$V$22="X")*ISNUMBER('Registro Notas'!$D8:$R8))=0, "-", SUMPRODUCT(('Matriz Criterios'!$H$22:$V$22="X")*ISNUMBER('Registro Notas'!$D8:$R8)*'Registro Notas'!$D8:$R8)/SUMPRODUCT(('Matriz Criterios'!$H$22:$V$22="X")*ISNUMBER('Registro Notas'!$D8:$R8))) | T8: =IF(SUMPRODUCT(('Matriz Criterios'!$H$23:$V$23="X")*ISNUMBER('Registro Notas'!$D8:$R8))=0, "-", SUMPRODUCT(('Matriz Criterios'!$H$23:$V$23="X")*ISNUMBER('Registro Notas'!$D8:$R8)*'Registro Notas'!$D8:$R8)/SUMPRODUCT(('Matriz Criterios'!$H$23:$V$23="X")*ISNUMBER('Registro Notas'!$D8:$R8))) | U8: =IF(SUMPRODUCT(('Matriz Criterios'!$H$24:$V$24="X")*ISNUMBER('Registro Notas'!$D8:$R8))=0, "-", SUMPRODUCT(('Matriz Criterios'!$H$24:$V$24="X")*ISNUMBER('Registro Notas'!$D8:$R8)*'Registro Notas'!$D8:$R8)/SUMPRODUCT(('Matriz Criterios'!$H$24:$V$24="X")*ISNUMBER('Registro Notas'!$D8:$R8))) | V8: =IF(SUMPRODUCT(('Matriz Criterios'!$H$25:$V$25="X")*ISNUMBER('Registro Notas'!$D8:$R8))=0, "-", SUMPRODUCT(('Matriz Criterios'!$H$25:$V$25="X")*ISNUMBER('Registro Notas'!$D8:$R8)*'Registro Notas'!$D8:$R8)/SUMPRODUCT(('Matriz Criterios'!$H$25:$V$25="X")*ISNUMBER('Registro Notas'!$D8:$R8))) | W8: =IF(SUMPRODUCT(('Matriz Criterios'!$H$26:$V$26="X")*ISNUMBER('Registro Notas'!$D8:$R8))=0, "-", SUMPRODUCT(('Matriz Criterios'!$H$26:$V$26="X")*ISNUMBER('Registro Notas'!$D8:$R8)*'Registro Notas'!$D8:$R8)/SUMPRODUCT(('Matriz Criterios'!$H$26:$V$26="X")*ISNUMBER('Registro Notas'!$D8:$R8))) | X8: =IF(SUMPRODUCT(('Matriz Criterios'!$H$27:$V$27="X")*ISNUMBER('Registro Notas'!$D8:$R8))=0, "-", SUMPRODUCT(('Matriz Criterios'!$H$27:$V$27="X")*ISNUMBER('Registro Notas'!$D8:$R8)*'Registro Notas'!$D8:$R8)/SUMPRODUCT(('Matriz Criterios'!$H$27:$V$27="X")*ISNUMBER('Registro Notas'!$D8:$R8))) | Y8: =IF(SUMPRODUCT(('Matriz Criterios'!$H$28:$V$28="X")*ISNUMBER('Registro Notas'!$D8:$R8))=0, "-", SUMPRODUCT(('Matriz Criterios'!$H$28:$V$28="X")*ISNUMBER('Registro Notas'!$D8:$R8)*'Registro Notas'!$D8:$R8)/SUMPRODUCT(('Matriz Criterios'!$H$28:$V$28="X")*ISNUMBER('Registro Notas'!$D8:$R8))) | Z8: =IF(SUMPRODUCT(('Matriz Criterios'!$H$29:$V$29="X")*ISNUMBER('Registro Notas'!$D8:$R8))=0, "-", SUMPRODUCT(('Matriz Criterios'!$H$29:$V$29="X")*ISNUMBER('Registro Notas'!$D8:$R8)*'Registro Notas'!$D8:$R8)/SUMPRODUCT(('Matriz Criterios'!$H$29:$V$29="X")*ISNUMBER('Registro Notas'!$D8:$R8))) | AA8: =IF(SUMPRODUCT(('Matriz Criterios'!$H$30:$V$30="X")*ISNUMBER('Registro Notas'!$D8:$R8))=0, "-", SUMPRODUCT(('Matriz Criterios'!$H$30:$V$30="X")*ISNUMBER('Registro Notas'!$D8:$R8)*'Registro Notas'!$D8:$R8)/SUMPRODUCT(('Matriz Criterios'!$H$30:$V$30="X")*ISNUMBER('Registro Notas'!$D8:$R8))) | AB8: =IF(SUMPRODUCT(('Matriz Criterios'!$H$31:$V$31="X")*ISNUMBER('Registro Notas'!$D8:$R8))=0, "-", SUMPRODUCT(('Matriz Criterios'!$H$31:$V$31="X")*ISNUMBER('Registro Notas'!$D8:$R8)*'Registro Notas'!$D8:$R8)/SUMPRODUCT(('Matriz Criterios'!$H$31:$V$31="X")*ISNUMBER('Registro Notas'!$D8:$R8))) | AC8: =IF(SUMPRODUCT(('Matriz Criterios'!$H$32:$V$32="X")*ISNUMBER('Registro Notas'!$D8:$R8))=0, "-", SUMPRODUCT(('Matriz Criterios'!$H$32:$V$32="X")*ISNUMBER('Registro Notas'!$D8:$R8)*'Registro Notas'!$D8:$R8)/SUMPRODUCT(('Matriz Criterios'!$H$32:$V$32="X")*ISNUMBER('Registro Notas'!$D8:$R8))) | AD8: =IF(SUMPRODUCT(('Matriz Criterios'!$H$33:$V$33="X")*ISNUMBER('Registro Notas'!$D8:$R8))=0, "-", SUMPRODUCT(('Matriz Criterios'!$H$33:$V$33="X")*ISNUMBER('Registro Notas'!$D8:$R8)*'Registro Notas'!$D8:$R8)/SUMPRODUCT(('Matriz Criterios'!$H$33:$V$33="X")*ISNUMBER('Registro Notas'!$D8:$R8))) | AE8: =IF(SUMPRODUCT(('Matriz Criterios'!$H$34:$V$34="X")*ISNUMBER('Registro Notas'!$D8:$R8))=0, "-", SUMPRODUCT(('Matriz Criterios'!$H$34:$V$34="X")*ISNUMBER('Registro Notas'!$D8:$R8)*'Registro Notas'!$D8:$R8)/SUMPRODUCT(('Matriz Criterios'!$H$34:$V$34="X")*ISNUMBER('Registro Notas'!$D8:$R8))) | AF8: =IF(SUMPRODUCT(('Matriz Criterios'!$H$35:$V$35="X")*ISNUMBER('Registro Notas'!$D8:$R8))=0, "-", SUMPRODUCT(('Matriz Criterios'!$H$35:$V$35="X")*ISNUMBER('Registro Notas'!$D8:$R8)*'Registro Notas'!$D8:$R8)/SUMPRODUCT(('Matriz Criterios'!$H$35:$V$35="X")*ISNUMBER('Registro Notas'!$D8:$R8))) | AG8: =IF(SUMPRODUCT(('Matriz Criterios'!$H$36:$V$36="X")*ISNUMBER('Registro Notas'!$D8:$R8))=0, "-", SUMPRODUCT(('Matriz Criterios'!$H$36:$V$36="X")*ISNUMBER('Registro Notas'!$D8:$R8)*'Registro Notas'!$D8:$R8)/SUMPRODUCT(('Matriz Criterios'!$H$36:$V$36="X")*ISNUMBER('Registro Notas'!$D8:$R8))) | AH8: =IF(SUMPRODUCT(('Matriz Criterios'!$H$37:$V$37="X")*ISNUMBER('Registro Notas'!$D8:$R8))=0, "-", SUMPRODUCT(('Matriz Criterios'!$H$37:$V$37="X")*ISNUMBER('Registro Notas'!$D8:$R8)*'Registro Notas'!$D8:$R8)/SUMPRODUCT(('Matriz Criterios'!$H$37:$V$37="X")*ISNUMBER('Registro Notas'!$D8:$R8))) | AI8: =IF(SUMPRODUCT(('Matriz Criterios'!$H$38:$V$38="X")*ISNUMBER('Registro Notas'!$D8:$R8))=0, "-", SUMPRODUCT(('Matriz Criterios'!$H$38:$V$38="X")*ISNUMBER('Registro Notas'!$D8:$R8)*'Registro Notas'!$D8:$R8)/SUMPRODUCT(('Matriz Criterios'!$H$38:$V$38="X")*ISNUMBER('Registro Notas'!$D8:$R8))) | AJ8: =IF(SUMPRODUCT(('Matriz Criterios'!$H$39:$V$39="X")*ISNUMBER('Registro Notas'!$D8:$R8))=0, "-", SUMPRODUCT(('Matriz Criterios'!$H$39:$V$39="X")*ISNUMBER('Registro Notas'!$D8:$R8)*'Registro Notas'!$D8:$R8)/SUMPRODUCT(('Matriz Criterios'!$H$39:$V$39="X")*ISNUMBER('Registro Notas'!$D8:$R8))) | AK8: =IF(SUMPRODUCT(('Matriz Criterios'!$H$40:$V$40="X")*ISNUMBER('Registro Notas'!$D8:$R8))=0, "-", SUMPRODUCT(('Matriz Criterios'!$H$40:$V$40="X")*ISNUMBER('Registro Notas'!$D8:$R8)*'Registro Notas'!$D8:$R8)/SUMPRODUCT(('Matriz Criterios'!$H$40:$V$40="X")*ISNUMBER('Registro Notas'!$D8:$R8))) | AL8: =IF(SUMPRODUCT(('Matriz Criterios'!$H$41:$V$41="X")*ISNUMBER('Registro Notas'!$D8:$R8))=0, "-", SUMPRODUCT(('Matriz Criterios'!$H$41:$V$41="X")*ISNUMBER('Registro Notas'!$D8:$R8)*'Registro Notas'!$D8:$R8)/SUMPRODUCT(('Matriz Criterios'!$H$41:$V$41="X")*ISNUMBER('Registro Notas'!$D8:$R8))) | AM8: =IF(SUMPRODUCT(('Matriz Criterios'!$H$42:$V$42="X")*ISNUMBER('Registro Notas'!$D8:$R8))=0, "-", SUMPRODUCT(('Matriz Criterios'!$H$42:$V$42="X")*ISNUMBER('Registro Notas'!$D8:$R8)*'Registro Notas'!$D8:$R8)/SUMPRODUCT(('Matriz Criterios'!$H$42:$V$42="X")*ISNUMBER('Registro Notas'!$D8:$R8))) | AN8: =IF(SUMPRODUCT(('Matriz Criterios'!$H$43:$V$43="X")*ISNUMBER('Registro Notas'!$D8:$R8))=0, "-", SUMPRODUCT(('Matriz Criterios'!$H$43:$V$43="X")*ISNUMBER('Registro Notas'!$D8:$R8)*'Registro Notas'!$D8:$R8)/SUMPRODUCT(('Matriz Criterios'!$H$43:$V$43="X")*ISNUMBER('Registro Notas'!$D8:$R8))) | AO8: =IF(SUMPRODUCT(('Matriz Criterios'!$H$44:$V$44="X")*ISNUMBER('Registro Notas'!$D8:$R8))=0, "-", SUMPRODUCT(('Matriz Criterios'!$H$44:$V$44="X")*ISNUMBER('Registro Notas'!$D8:$R8)*'Registro Notas'!$D8:$R8)/SUMPRODUCT(('Matriz Criterios'!$H$44:$V$44="X")*ISNUMBER('Registro Notas'!$D8:$R8))) | AP8: =IF(SUMPRODUCT(('Matriz Criterios'!$H$45:$V$45="X")*ISNUMBER('Registro Notas'!$D8:$R8))=0, "-", SUMPRODUCT(('Matriz Criterios'!$H$45:$V$45="X")*ISNUMBER('Registro Notas'!$D8:$R8)*'Registro Notas'!$D8:$R8)/SUMPRODUCT(('Matriz Criterios'!$H$45:$V$45="X")*ISNUMBER('Registro Notas'!$D8:$R8))) | AQ8: =AVERAGE(C8:AP8) | AR8: =COUNTIF(C8:AP8, ">=5")
